Workbook
Name \p: #REF!
Name _70IJ610001: Table18[#All]
Name _Order1: 255
Name _Order2: 255
Name _Regression_Int: 1
Name a: #REF!
Name a_dash: #REF!
Name AA: #REF!
Name aaa: "기술자료"
Name agdump: #REF!
Name agedump: #REF!
Name agencydump: #REF!
Name AGENCYLY: #REF!
Name AGENCYPLAN: #REF!
Name anchor: #REF!
Name api_version: '[1]Page 1'!$B$6
Name b: #REF!
Name b_dash: #REF!
Name bmsum: #REF!
Name c_margin: #REF!
Name CalcAgencyPrice: #REF!
Name CapacityAtMaximumViscosity: '[2]API 676'!#REF!
Name Clearsheet2: LoadList!Clearsheet2
Name Clearsheet2: [0]!Clearsheet2
Name coat: #REF!
Name Commission: #REF!
Name crush_s: #REF!
Name DaRWk1: #REF!
Name DaRWk10: #REF!
Name DaRWk11: #REF!
Name DaRWk12: #REF!
Name DaRWk2: #REF!
Name DaRWk3: #REF!
Name DaRWk4: #REF!
Name DaRWk5: #REF!
Name DaRWk6: #REF!
Name DaRWk8: #REF!
Name DaRwk9: #REF!
Name DATE: '[3]P. 1, Scope'!$M$5
Name DaWk7: #REF!
Name dbrwk1: #REF!
Name dbrwk10: #REF!
Name dbrwk11: #REF!
Name dbrwk12: #REF!
Name dbrwk2: #REF!
Name dbrwk3: #REF!
Name dbrwk4: #REF!
Name dbrwk5: #REF!
Name dbrwk6: #REF!
Name dbrwk7: #REF!
Name dbrwk8: #REF!
Name dbrwk9: #REF!
Name dcrwk1: #REF!
Name dcrwk10: #REF!
Name dcrwk11: #REF!
Name dcrwk12: #REF!
Name dcrwk2: #REF!
Name dcrwk3: #REF!
Name dcrwk4: #REF!
Name dcrwk5: #REF!

Sheet Sheet1
A1: Create a technical specification for Distribution Board based on the sources. Please note that this is for Biomethanol project.
A2: Create a technical specification for Load Shedding System based on the sources. Please note that this is for Biomethanol project.
A3: Create a technical specification for Power Factor Correction Panel based on the sources. Please note that this is for Biomethanol project.

Sheet HVAC_MCC
A1: 70-IK-09-0001 (CANCELLED)
A3: TAGS | B3: BUS | C3: RATED POWER | D3: FULL LOAD CURRENT | E3: Starter Type | F3: CIRCUIT TYPE | G3: E_UNITS | H3: REMARKS | Q3: feeder qty | R3: 20% SPARE
A4: WH-AHU-001 | B4: A | C4: 78.8 | D4: 124.83439 | E4: {=_xlfn.LET( _xlpm.tag, UPPER(TRIM(A4)), _xlpm.kw, N(C4), _xlpm.parts, _xlfn.TEXTSPLIT(_xlpm.tag,"-"), _xlpm.mid, IF(COUNTA(_xlpm.parts)>=2, INDEX(_xlpm.parts,1,2), ""), _xlpm.mapCodes, {"AHU";"CWP";"EF";"ACWC";"ACCU";"EDH";"WWG";"WWP";"HD"}, _xlpm.mapType, {"M";"M";"M";"F";"F";"F";"F";"F";"F"}, _xlpm.codeType, _xlfn.XLOOKUP(_xlpm.mid, _xlpm.mapCodes, _xlpm.mapType, ""), IF(_xlpm.codeType="F","F", IF(_xlpm.codeType="M", _xlfn.IFS( _xlpm.mid="AHU", "M-E1", AND(_xlpm.kw>=0.37, _xlpm.kw<=15), "M-A1", AND(_xlpm.kw>=18.5, _xlpm.kw<22), "M-A1", AND(_xlpm.kw>=22, _xlpm.kw<=37), "M-B1", AND(_xlpm.kw>=45, _xlpm.kw<=75), "M-B1", AND(_xlpm.kw>=90, _xlpm.kw<=110), "M-B1", AND(_xlpm.kw>110, _xlpm.kw<132), "M-C1", AND(_xlpm.kw>=132, _xlpm.kw<=200), "M-D1", _xlpm.kw>200, "M-E1", TRUE, "<review>" ), "<review>" ) ) )} -> M-E1 | F4: {=_xlfn.LET( _xlpm.tag, UPPER(TRIM(A4)), _xlpm.kw, N(C4), _xlpm.flc, N(D4), _xlpm.I_MCCB, 160, _xlpm.I_ACB, 630, _xlpm.tACB, "400V Air Circuit Breaker(ACB) Feeder Cubicle (per Dwg LV1)", _xlpm.tMCCB_HI, "400V MCCB Feeder Cubicle (I > 160A, per Dwg LV3)", _xlpm.tMCCB_LO, "400V MCCB Feeder Cubicle (I < 160A, per Dwg LV4)", _xlpm.tM_LV_DOL, "400V DOL Motor Starter Cubicle", _xlpm.parts, _xlfn.TEXTSPLIT(_xlpm.tag,"-"), _xlpm.mid, IF(COUNTA(_xlpm.parts)>=2, INDEX(_xlpm.parts,1,2), ""), _xlpm.mapCodes, {"AHU";"CWP";"EF";"ACWC";"ACCU";"EDH";"WWG";"WWP";"HD"}, _xlpm.mapType, {"M";"M";"M";"F";"F";"F";"F";"F";"F"}, _xlpm.codeType, _xlfn.XLOOKUP(_xlpm.mid, _xlpm.mapCodes, _xlpm.mapType, ""), _xlpm.motorClass, IF(_xlpm.codeType="M", _xlfn.IFS( _xlpm.mid="AHU", "M-E1", AND(_xlpm.kw>=0.37, _xlpm.kw<=15), "M-A1", AND(_xlpm.kw>=18.5, _xlpm.kw<22), "M-A1", AND(_xlpm.kw>=22, _xlpm.kw<=37), "M-B1", AND(_xlpm.kw>=45, _xlpm.kw<=75), "M-B1", AND(_xlpm.kw>=90, _xlpm.kw<=110), "M-B1", AND(_xlpm.kw>110, _xlpm.kw<132), "M-C1", AND(_xlpm.kw>=132, _xlpm.kw<=200), "M-D1", _xlpm.kw>200, "M-E1", TRUE, "<review>" ), "" ), _xlpm.FeederSel, IF(_xlpm.flc>=_xlpm.I_ACB, _xlpm.tACB, IF(_xlpm.flc>_xlpm.I_MCCB, _xlpm.tMCCB_HI, _xlpm.tMCCB_LO)), IF(_xlpm.codeType="F", _xlpm.FeederSel, IF(_xlpm.codeType="M", IF(_xlpm.motorClass="<review>", "<review>", _xlpm.tM_LV_DOL), "CHECK TAG CODE: "&_xlpm.mid ) ) )} -> 400V DOL Motor Starter Cubicle | G4: {=_xlfn.LET( _xlpm.c, UPPER(TRIM(_81IK6100018[[#This Row],[Starter Type]])), _xlpm.kw, N(_81IK6100018[[#This Row],[RATED POWER]]), _xlpm.flc, N(_81IK6100018[[#This Row],[FULL LOAD CURRENT]]), _xlpm.feederType, IFERROR( _xlfn.IFS( _xlpm.c="M-A1", "M_A1", _xlpm.c="M-B1", "M_B1", _xlpm.c="M-C1", "M_C1", _xlpm.c="M-D1", "M_D1", _xlpm.c="M-E1", "M_E1", _xlpm.c="U", "UPS", _xlpm.c="F", "FEEDER", _xlpm.c="L", "LIGHT", _xlpm.c="H", "HEATER", ISNUMBER(SEARCH("ACB", _xlpm.c)), "ACB", ISNUMBER(SEARCH("I > 160A", _xlpm.c)), "MCCB_HI", ISNUMBER(SEARCH("I < 160A", _xlpm.c)), "MCCB_LO", ISNUMBER(SEARCH("3PH+N+PE", _xlpm.c)), "3PNPE", ISNUMBER(SEARCH("SCR", _xlpm.c)), "SCR", ISNUMBER(SEARCH("VSD", _xlpm.c)), "MCCB_VSD", ISNUMBER(SEARCH("FVNR", _xlpm.c)), "FVNR", TRUE, "OTHER" ), "OTHER" ), _xlpm.LowE, _xlfn.LAMBDA(_xlpm.a, IF(_xlpm.a<=50, "8E", IF(_xlpm.a<=100, "12E", "16E"))), _xlpm.HighE, _xlfn.LAMBDA(_xlpm.a, IF(_xlpm.a<=250, "16E", IF(_xlpm.a<=400, "24E", "36E"))), _xlpm.FeederE, IF(_xlpm.flc<=32, "8E/4", IF(_xlpm.flc<=160, _xlpm.LowE(_xlpm.flc), _xlpm.HighE(_xlpm.flc))), _xlfn.IFS( _xlpm.feederType="ACB", "72E", _xlpm.feederType="MCCB_LO", _xlpm.LowE(_xlpm.flc), _xlpm.feederType="MCCB_HI", _xlpm.HighE(_xlpm.flc), _xlpm.feederType="3PNPE", _xlpm.LowE(_xlpm.flc), _xlpm.feederType="SCR", IF(_xlpm.flc<=63, "8E", IF(_xlpm.flc<=125, "12E", IF(_xlpm.flc<=250, "24E", "36E"))), _xlpm.feederType="MCCB_VSD",_xlpm.HighE(_xlpm.flc), _xlpm.feederType="FVNR", IF(_xlpm.kw<=55, "16E", IF(_xlpm.kw<=90, "24E", "36E")), _xlpm.feederType="M_A1", IF(_xlpm.kw<=15, "8E/4", "8E"), _xlpm.feederType="M_B1", IF(_xlpm.kw<=37, "8E", "12E"), _xlpm.feederType="M_C1", IF(_xlpm.kw<132, "12E", "16E"), _xlpm.feederType="M_D1", "16E", _xlpm.feederType="M_E1", "24E", _xlpm.feederType="UPS", IF(_xlpm.flc<=50, "8E", IF(_xlpm.flc<=100, "12E", IF(_xlpm.flc<=250, "16E", IF(_xlpm.flc<=400, "24E", "36E")))), _xlpm.feederType="FEEDER", _xlpm.FeederE, _xlpm.feederType="LIGHT", _xlpm.FeederE, _xlpm.feederType="HEATER", _xlpm.FeederE, TRUE, "<review>" ) )} -> 24E | N4: M-B1 | O4: 400V DOL Motor Starter Cubicle | P4: 36E | Q4: =COUNTIFS($E$4:$E$18,N4,$F$4:$F$18,O4,$G$4:$G$18,P4) -> 0 | R4: =ROUNDUP(Q4*0.2,0) -> 0
A5: WH-ACWC-001 | B5: A | C5: 80.52 | D5: 127.55921 | E5: {=_xlfn.LET( _xlpm.tag, UPPER(TRIM(A5)), _xlpm.kw, N(C5), _xlpm.parts, _xlfn.TEXTSPLIT(_xlpm.tag,"-"), _xlpm.mid, IF(COUNTA(_xlpm.parts)>=2, INDEX(_xlpm.parts,1,2), ""), _xlpm.mapCodes, {"AHU";"CWP";"EF";"ACWC";"ACCU";"EDH";"WWG";"WWP";"HD"}, _xlpm.mapType, {"M";"M";"M";"F";"F";"F";"F";"F";"F"}, _xlpm.codeType, _xlfn.XLOOKUP(_xlpm.mid, _xlpm.mapCodes, _xlpm.mapType, ""), IF(_xlpm.codeType="F","F", IF(_xlpm.codeType="M", _xlfn.IFS( _xlpm.mid="AHU", "M-E1", AND(_xlpm.kw>=0.37, _xlpm.kw<=15), "M-A1", AND(_xlpm.kw>=18.5, _xlpm.kw<22), "M-A1", AND(_xlpm.kw>=22, _xlpm.kw<=37), "M-B1", AND(_xlpm.kw>=45, _xlpm.kw<=75), "M-B1", AND(_xlpm.kw>=90, _xlpm.kw<=110), "M-B1", AND(_xlpm.kw>110, _xlpm.kw<132), "M-C1", AND(_xlpm.kw>=132, _xlpm.kw<=200), "M-D1", _xlpm.kw>200, "M-E1", TRUE, "<review>" ), "<review>" ) ) )} -> F | F5: {=_xlfn.LET( _xlpm.tag, UPPER(TRIM(A5)), _xlpm.kw, N(C5), _xlpm.flc, N(D5), _xlpm.I_MCCB, 160, _xlpm.I_ACB, 630, _xlpm.tACB, "400V Air Circuit Breaker(ACB) Feeder Cubicle (per Dwg LV1)", _xlpm.tMCCB_HI, "400V MCCB Feeder Cubicle (I > 160A, per Dwg LV3)", _xlpm.tMCCB_LO, "400V MCCB Feeder Cubicle (I < 160A, per Dwg LV4)", _xlpm.tM_LV_DOL, "400V DOL Motor Starter Cubicle", _xlpm.parts, _xlfn.TEXTSPLIT(_xlpm.tag,"-"), _xlpm.mid, IF(COUNTA(_xlpm.parts)>=2, INDEX(_xlpm.parts,1,2), ""), _xlpm.mapCodes, {"AHU";"CWP";"EF";"ACWC";"ACCU";"EDH";"WWG";"WWP";"HD"}, _xlpm.mapType, {"M";"M";"M";"F";"F";"F";"F";"F";"F"}, _xlpm.codeType, _xlfn.XLOOKUP(_xlpm.mid, _xlpm.mapCodes, _xlpm.mapType, ""), _xlpm.motorClass, IF(_xlpm.codeType="M", _xlfn.IFS( _xlpm.mid="AHU", "M-E1", AND(_xlpm.kw>=0.37, _xlpm.kw<=15), "M-A1", AND(_xlpm.kw>=18.5, _xlpm.kw<22), "M-A1", AND(_xlpm.kw>=22, _xlpm.kw<=37), "M-B1", AND(_xlpm.kw>=45, _xlpm.kw<=75), "M-B1", AND(_xlpm.kw>=90, _xlpm.kw<=110), "M-B1", AND(_xlpm.kw>110, _xlpm.kw<132), "M-C1", AND(_xlpm.kw>=132, _xlpm.kw<=200), "M-D1", _xlpm.kw>200, "M-E1", TRUE, "<review>" ), "" ), _xlpm.FeederSel, IF(_xlpm.flc>=_xlpm.I_ACB, _xlpm.tACB, IF(_xlpm.flc>_xlpm.I_MCCB, _xlpm.tMCCB_HI, _xlpm.tMCCB_LO)), IF(_xlpm.codeType="F", _xlpm.FeederSel, IF(_xlpm.codeType="M", IF(_xlpm.motorClass="<review>", "<review>", _xlpm.tM_LV_DOL), "CHECK TAG CODE: "&_xlpm.mid ) ) )} -> 400V MCCB Feeder Cubicle (I < 160A, per Dwg LV4) | G5: {=_xlfn.LET( _xlpm.c, UPPER(TRIM(_81IK6100018[[#This Row],[Starter Type]])), _xlpm.kw, N(_81IK6100018[[#This Row],[RATED POWER]]), _xlpm.flc, N(_81IK6100018[[#This Row],[FULL LOAD CURRENT]]), _xlpm.feederType, IFERROR( _xlfn.IFS( _xlpm.c="M-A1", "M_A1", _xlpm.c="M-B1", "M_B1", _xlpm.c="M-C1", "M_C1", _xlpm.c="M-D1", "M_D1", _xlpm.c="M-E1", "M_E1", _xlpm.c="U", "UPS", _xlpm.c="F", "FEEDER", _xlpm.c="L", "LIGHT", _xlpm.c="H", "HEATER", ISNUMBER(SEARCH("ACB", _xlpm.c)), "ACB", ISNUMBER(SEARCH("I > 160A", _xlpm.c)), "MCCB_HI", ISNUMBER(SEARCH("I < 160A", _xlpm.c)), "MCCB_LO", ISNUMBER(SEARCH("3PH+N+PE", _xlpm.c)), "3PNPE", ISNUMBER(SEARCH("SCR", _xlpm.c)), "SCR", ISNUMBER(SEARCH("VSD", _xlpm.c)), "MCCB_VSD", ISNUMBER(SEARCH("FVNR", _xlpm.c)), "FVNR", TRUE, "OTHER" ), "OTHER" ), _xlpm.LowE, _xlfn.LAMBDA(_xlpm.a, IF(_xlpm.a<=50, "8E", IF(_xlpm.a<=100, "12E", "16E"))), _xlpm.HighE, _xlfn.LAMBDA(_xlpm.a, IF(_xlpm.a<=250, "16E", IF(_xlpm.a<=400, "24E", "36E"))), _xlpm.FeederE, IF(_xlpm.flc<=32, "8E/4", IF(_xlpm.flc<=160, _xlpm.LowE(_xlpm.flc), _xlpm.HighE(_xlpm.flc))), _xlfn.IFS( _xlpm.feederType="ACB", "72E", _xlpm.feederType="MCCB_LO", _xlpm.LowE(_xlpm.flc), _xlpm.feederType="MCCB_HI", _xlpm.HighE(_xlpm.flc), _xlpm.feederType="3PNPE", _xlpm.LowE(_xlpm.flc), _xlpm.feederType="SCR", IF(_xlpm.flc<=63, "8E", IF(_xlpm.flc<=125, "12E", IF(_xlpm.flc<=250, "24E", "36E"))), _xlpm.feederType="MCCB_VSD",_xlpm.HighE(_xlpm.flc), _xlpm.feederType="FVNR", IF(_xlpm.kw<=55, "16E", IF(_xlpm.kw<=90, "24E", "36E")), _xlpm.feederType="M_A1", IF(_xlpm.kw<=15, "8E/4", "8E"), _xlpm.feederType="M_B1", IF(_xlpm.kw<=37, "8E", "12E"), _xlpm.feederType="M_C1", IF(_xlpm.kw<132, "12E", "16E"), _xlpm.feederType="M_D1", "16E", _xlpm.feederType="M_E1", "24E", _xlpm.feederType="UPS", IF(_xlpm.flc<=50, "8E", IF(_xlpm.flc<=100, "12E", IF(_xlpm.flc<=250, "16E", IF(_xlpm.flc<=400, "24E", "36E")))), _xlpm.feederType="FEEDER", _xlpm.FeederE, _xlpm.feederType="LIGHT", _xlpm.FeederE, _xlpm.feederType="HEATER", _xlpm.FeederE, TRUE, "<review>" ) )} -> 16E | N5: F | O5: 400V MCCB Feeder Cubicle (I < 160A, per Dwg LV4) | P5: 8E | Q5: =COUNTIFS($E$4:$E$18,N5,$F$4:$F$18,O5,$G$4:$G$18,P5) -> 2 | R5: =ROUNDUP(Q5*0.2,0) -> 1
A6: WH-CWP-001A | B6: A | C6: 4.37 | D6: 6.9229226 | E6: {=_xlfn.LET( _xlpm.tag, UPPER(TRIM(A6)), _xlpm.kw, N(C6), _xlpm.parts, _xlfn.TEXTSPLIT(_xlpm.tag,"-"), _xlpm.mid, IF(COUNTA(_xlpm.parts)>=2, INDEX(_xlpm.parts,1,2), ""), _xlpm.mapCodes, {"AHU";"CWP";"EF";"ACWC";"ACCU";"EDH";"WWG";"WWP";"HD"}, _xlpm.mapType, {"M";"M";"M";"F";"F";"F";"F";"F";"F"}, _xlpm.codeType, _xlfn.XLOOKUP(_xlpm.mid, _xlpm.mapCodes, _xlpm.mapType, ""), IF(_xlpm.codeType="F","F", IF(_xlpm.codeType="M", _xlfn.IFS( _xlpm.mid="AHU", "M-E1", AND(_xlpm.kw>=0.37, _xlpm.kw<=15), "M-A1", AND(_xlpm.kw>=18.5, _xlpm.kw<22), "M-A1", AND(_xlpm.kw>=22, _xlpm.kw<=37), "M-B1", AND(_xlpm.kw>=45, _xlpm.kw<=75), "M-B1", AND(_xlpm.kw>=90, _xlpm.kw<=110), "M-B1", AND(_xlpm.kw>110, _xlpm.kw<132), "M-C1", AND(_xlpm.kw>=132, _xlpm.kw<=200), "M-D1", _xlpm.kw>200, "M-E1", TRUE, "<review>" ), "<review>" ) ) )} -> M-A1 | F6: {=_xlfn.LET( _xlpm.tag, UPPER(TRIM(A6)), _xlpm.kw, N(C6), _xlpm.flc, N(D6), _xlpm.I_MCCB, 160, _xlpm.I_ACB, 630, _xlpm.tACB, "400V Air Circuit Breaker(ACB) Feeder Cubicle (per Dwg LV1)", _xlpm.tMCCB_HI, "400V MCCB Feeder Cubicle (I > 160A, per Dwg LV3)", _xlpm.tMCCB_LO, "400V MCCB Feeder Cubicle (I < 160A, per Dwg LV4)", _xlpm.tM_LV_DOL, "400V DOL Motor Starter Cubicle", _xlpm.parts, _xlfn.TEXTSPLIT(_xlpm.tag,"-"), _xlpm.mid, IF(COUNTA(_xlpm.parts)>=2, INDEX(_xlpm.parts,1,2), ""), _xlpm.mapCodes, {"AHU";"CWP";"EF";"ACWC";"ACCU";"EDH";"WWG";"WWP";"HD"}, _xlpm.mapType, {"M";"M";"M";"F";"F";"F";"F";"F";"F"}, _xlpm.codeType, _xlfn.XLOOKUP(_xlpm.mid, _xlpm.mapCodes, _xlpm.mapType, ""), _xlpm.motorClass, IF(_xlpm.codeType="M", _xlfn.IFS( _xlpm.mid="AHU", "M-E1", AND(_xlpm.kw>=0.37, _xlpm.kw<=15), "M-A1", AND(_xlpm.kw>=18.5, _xlpm.kw<22), "M-A1", AND(_xlpm.kw>=22, _xlpm.kw<=37), "M-B1", AND(_xlpm.kw>=45, _xlpm.kw<=75), "M-B1", AND(_xlpm.kw>=90, _xlpm.kw<=110), "M-B1", AND(_xlpm.kw>110, _xlpm.kw<132), "M-C1", AND(_xlpm.kw>=132, _xlpm.kw<=200), "M-D1", _xlpm.kw>200, "M-E1", TRUE, "<review>" ), "" ), _xlpm.FeederSel, IF(_xlpm.flc>=_xlpm.I_ACB, _xlpm.tACB, IF(_xlpm.flc>_xlpm.I_MCCB, _xlpm.tMCCB_HI, _xlpm.tMCCB_LO)), IF(_xlpm.codeType="F", _xlpm.FeederSel, IF(_xlpm.codeType="M", IF(_xlpm.motorClass="<review>", "<review>", _xlpm.tM_LV_DOL), "CHECK TAG CODE: "&_xlpm.mid ) ) )} -> 400V DOL Motor Starter Cubicle | G6: {=_xlfn.LET( _xlpm.c, UPPER(TRIM(_81IK6100018[[#This Row],[Starter Type]])), _xlpm.kw, N(_81IK6100018[[#This Row],[RATED POWER]]), _xlpm.flc, N(_81IK6100018[[#This Row],[FULL LOAD CURRENT]]), _xlpm.feederType, IFERROR( _xlfn.IFS( _xlpm.c="M-A1", "M_A1", _xlpm.c="M-B1", "M_B1", _xlpm.c="M-C1", "M_C1", _xlpm.c="M-D1", "M_D1", _xlpm.c="M-E1", "M_E1", _xlpm.c="U", "UPS", _xlpm.c="F", "FEEDER", _xlpm.c="L", "LIGHT", _xlpm.c="H", "HEATER", ISNUMBER(SEARCH("ACB", _xlpm.c)), "ACB", ISNUMBER(SEARCH("I > 160A", _xlpm.c)), "MCCB_HI", ISNUMBER(SEARCH("I < 160A", _xlpm.c)), "MCCB_LO", ISNUMBER(SEARCH("3PH+N+PE", _xlpm.c)), "3PNPE", ISNUMBER(SEARCH("SCR", _xlpm.c)), "SCR", ISNUMBER(SEARCH("VSD", _xlpm.c)), "MCCB_VSD", ISNUMBER(SEARCH("FVNR", _xlpm.c)), "FVNR", TRUE, "OTHER" ), "OTHER" ), _xlpm.LowE, _xlfn.LAMBDA(_xlpm.a, IF(_xlpm.a<=50, "8E", IF(_xlpm.a<=100, "12E", "16E"))), _xlpm.HighE, _xlfn.LAMBDA(_xlpm.a, IF(_xlpm.a<=250, "16E", IF(_xlpm.a<=400, "24E", "36E"))), _xlpm.FeederE, IF(_xlpm.flc<=32, "8E/4", IF(_xlpm.flc<=160, _xlpm.LowE(_xlpm.flc), _xlpm.HighE(_xlpm.flc))), _xlfn.IFS( _xlpm.feederType="ACB", "72E", _xlpm.feederType="MCCB_LO", _xlpm.LowE(_xlpm.flc), _xlpm.feederType="MCCB_HI", _xlpm.HighE(_xlpm.flc), _xlpm.feederType="3PNPE", _xlpm.LowE(_xlpm.flc), _xlpm.feederType="SCR", IF(_xlpm.flc<=63, "8E", IF(_xlpm.flc<=125, "12E", IF(_xlpm.flc<=250, "24E", "36E"))), _xlpm.feederType="MCCB_VSD",_xlpm.HighE(_xlpm.flc), _xlpm.feederType="FVNR", IF(_xlpm.kw<=55, "16E", IF(_xlpm.kw<=90, "24E", "36E")), _xlpm.feederType="M_A1", IF(_xlpm.kw<=15, "8E/4", "8E"), _xlpm.feederType="M_B1", IF(_xlpm.kw<=37, "8E", "12E"), _xlpm.feederType="M_C1", IF(_xlpm.kw<132, "12E", "16E"), _xlpm.feederType="M_D1", "16E", _xlpm.feederType="M_E1", "24E", _xlpm.feederType="UPS", IF(_xlpm.flc<=50, "8E", IF(_xlpm.flc<=100, "12E", IF(_xlpm.flc<=250, "16E", IF(_xlpm.flc<=400, "24E", "36E")))), _xlpm.feederType="FEEDER", _xlpm.FeederE, _xlpm.feederType="LIGHT", _xlpm.FeederE, _xlpm.feederType="HEATER", _xlpm.FeederE, TRUE, "<review>" ) )} -> 8E/4 | N6: U | O6: 400V UPS Feeder Cubicle | P6: 8E | Q6: =COUNTIFS($E$4:$E$18,N6,$F$4:$F$18,O6,$G$4:$G$18,P6) -> 0 | R6: =ROUNDUP(Q6*0.2,0) -> 0
A7: WH-CWP-001B | B7: A | C7: 4.37 | D7: 6.9229226 | E7: {=_xlfn.LET( _xlpm.tag, UPPER(TRIM(A7)), _xlpm.kw, N(C7), _xlpm.parts, _xlfn.TEXTSPLIT(_xlpm.tag,"-"), _xlpm.mid, IF(COUNTA(_xlpm.parts)>=2, INDEX(_xlpm.parts,1,2), ""), _xlpm.mapCodes, {"AHU";"CWP";"EF";"ACWC";"ACCU";"EDH";"WWG";"WWP";"HD"}, _xlpm.mapType, {"M";"M";"M";"F";"F";"F";"F";"F";"F"}, _xlpm.codeType, _xlfn.XLOOKUP(_xlpm.mid, _xlpm.mapCodes, _xlpm.mapType, ""), IF(_xlpm.codeType="F","F", IF(_xlpm.codeType="M", _xlfn.IFS( _xlpm.mid="AHU", "M-E1", AND(_xlpm.kw>=0.37, _xlpm.kw<=15), "M-A1", AND(_xlpm.kw>=18.5, _xlpm.kw<22), "M-A1", AND(_xlpm.kw>=22, _xlpm.kw<=37), "M-B1", AND(_xlpm.kw>=45, _xlpm.kw<=75), "M-B1", AND(_xlpm.kw>=90, _xlpm.kw<=110), "M-B1", AND(_xlpm.kw>110, _xlpm.kw<132), "M-C1", AND(_xlpm.kw>=132, _xlpm.kw<=200), "M-D1", _xlpm.kw>200, "M-E1", TRUE, "<review>" ), "<review>" ) ) )} -> M-A1 | F7: {=_xlfn.LET( _xlpm.tag, UPPER(TRIM(A7)), _xlpm.kw, N(C7), _xlpm.flc, N(D7), _xlpm.I_MCCB, 160, _xlpm.I_ACB, 630, _xlpm.tACB, "400V Air Circuit Breaker(ACB) Feeder Cubicle (per Dwg LV1)", _xlpm.tMCCB_HI, "400V MCCB Feeder Cubicle (I > 160A, per Dwg LV3)", _xlpm.tMCCB_LO, "400V MCCB Feeder Cubicle (I < 160A, per Dwg LV4)", _xlpm.tM_LV_DOL, "400V DOL Motor Starter Cubicle", _xlpm.parts, _xlfn.TEXTSPLIT(_xlpm.tag,"-"), _xlpm.mid, IF(COUNTA(_xlpm.parts)>=2, INDEX(_xlpm.parts,1,2), ""), _xlpm.mapCodes, {"AHU";"CWP";"EF";"ACWC";"ACCU";"EDH";"WWG";"WWP";"HD"}, _xlpm.mapType, {"M";"M";"M";"F";"F";"F";"F";"F";"F"}, _xlpm.codeType, _xlfn.XLOOKUP(_xlpm.mid, _xlpm.mapCodes, _xlpm.mapType, ""), _xlpm.motorClass, IF(_xlpm.codeType="M", _xlfn.IFS( _xlpm.mid="AHU", "M-E1", AND(_xlpm.kw>=0.37, _xlpm.kw<=15), "M-A1", AND(_xlpm.kw>=18.5, _xlpm.kw<22), "M-A1", AND(_xlpm.kw>=22, _xlpm.kw<=37), "M-B1", AND(_xlpm.kw>=45, _xlpm.kw<=75), "M-B1", AND(_xlpm.kw>=90, _xlpm.kw<=110), "M-B1", AND(_xlpm.kw>110, _xlpm.kw<132), "M-C1", AND(_xlpm.kw>=132, _xlpm.kw<=200), "M-D1", _xlpm.kw>200, "M-E1", TRUE, "<review>" ), "" ), _xlpm.FeederSel, IF(_xlpm.flc>=_xlpm.I_ACB, _xlpm.tACB, IF(_xlpm.flc>_xlpm.I_MCCB, _xlpm.tMCCB_HI, _xlpm.tMCCB_LO)), IF(_xlpm.codeType="F", _xlpm.FeederSel, IF(_xlpm.codeType="M", IF(_xlpm.motorClass="<review>", "<review>", _xlpm.tM_LV_DOL), "CHECK TAG CODE: "&_xlpm.mid ) ) )} -> 400V DOL Motor Starter Cubicle | G7: {=_xlfn.LET( _xlpm.c, UPPER(TRIM(_81IK6100018[[#This Row],[Starter Type]])), _xlpm.kw, N(_81IK6100018[[#This Row],[RATED POWER]]), _xlpm.flc, N(_81IK6100018[[#This Row],[FULL LOAD CURRENT]]), _xlpm.feederType, IFERROR( _xlfn.IFS( _xlpm.c="M-A1", "M_A1", _xlpm.c="M-B1", "M_B1", _xlpm.c="M-C1", "M_C1", _xlpm.c="M-D1", "M_D1", _xlpm.c="M-E1", "M_E1", _xlpm.c="U", "UPS", _xlpm.c="F", "FEEDER", _xlpm.c="L", "LIGHT", _xlpm.c="H", "HEATER", ISNUMBER(SEARCH("ACB", _xlpm.c)), "ACB", ISNUMBER(SEARCH("I > 160A", _xlpm.c)), "MCCB_HI", ISNUMBER(SEARCH("I < 160A", _xlpm.c)), "MCCB_LO", ISNUMBER(SEARCH("3PH+N+PE", _xlpm.c)), "3PNPE", ISNUMBER(SEARCH("SCR", _xlpm.c)), "SCR", ISNUMBER(SEARCH("VSD", _xlpm.c)), "MCCB_VSD", ISNUMBER(SEARCH("FVNR", _xlpm.c)), "FVNR", TRUE, "OTHER" ), "OTHER" ), _xlpm.LowE, _xlfn.LAMBDA(_xlpm.a, IF(_xlpm.a<=50, "8E", IF(_xlpm.a<=100, "12E", "16E"))), _xlpm.HighE, _xlfn.LAMBDA(_xlpm.a, IF(_xlpm.a<=250, "16E", IF(_xlpm.a<=400, "24E", "36E"))), _xlpm.FeederE, IF(_xlpm.flc<=32, "8E/4", IF(_xlpm.flc<=160, _xlpm.LowE(_xlpm.flc), _xlpm.HighE(_xlpm.flc))), _xlfn.IFS( _xlpm.feederType="ACB", "72E", _xlpm.feederType="MCCB_LO", _xlpm.LowE(_xlpm.flc), _xlpm.feederType="MCCB_HI", _xlpm.HighE(_xlpm.flc), _xlpm.feederType="3PNPE", _xlpm.LowE(_xlpm.flc), _xlpm.feederType="SCR", IF(_xlpm.flc<=63, "8E", IF(_xlpm.flc<=125, "12E", IF(_xlpm.flc<=250, "24E", "36E"))), _xlpm.feederType="MCCB_VSD",_xlpm.HighE(_xlpm.flc), _xlpm.feederType="FVNR", IF(_xlpm.kw<=55, "16E", IF(_xlpm.kw<=90, "24E", "36E")), _xlpm.feederType="M_A1", IF(_xlpm.kw<=15, "8E/4", "8E"), _xlpm.feederType="M_B1", IF(_xlpm.kw<=37, "8E", "12E"), _xlpm.feederType="M_C1", IF(_xlpm.kw<132, "12E", "16E"), _xlpm.feederType="M_D1", "16E", _xlpm.feederType="M_E1", "24E", _xlpm.feederType="UPS", IF(_xlpm.flc<=50, "8E", IF(_xlpm.flc<=100, "12E", IF(_xlpm.flc<=250, "16E", IF(_xlpm.flc<=400, "24E", "36E")))), _xlpm.feederType="FEEDER", _xlpm.FeederE, _xlpm.feederType="LIGHT", _xlpm.FeederE, _xlpm.feederType="HEATER", _xlpm.FeederE, TRUE, "<review>" ) )} -> 8E/4 | N7: U | O7: 400V UPS Feeder Cubicle | P7: 12E | Q7: =COUNTIFS($E$4:$E$18,N7,$F$4:$F$18,O7,$G$4:$G$18,P7) -> 0 | R7: =ROUNDUP(Q7*0.2,0) -> 0
A8: WH-ACCU-001 | B8: A | C8: 24.5 | D8: 38.812724 | E8: {=_xlfn.LET( _xlpm.tag, UPPER(TRIM(A8)), _xlpm.kw, N(C8), _xlpm.parts, _xlfn.TEXTSPLIT(_xlpm.tag,"-"), _xlpm.mid, IF(COUNTA(_xlpm.parts)>=2, INDEX(_xlpm.parts,1,2), ""), _xlpm.mapCodes, {"AHU";"CWP";"EF";"ACWC";"ACCU";"EDH";"WWG";"WWP";"HD"}, _xlpm.mapType, {"M";"M";"M";"F";"F";"F";"F";"F";"F"}, _xlpm.codeType, _xlfn.XLOOKUP(_xlpm.mid, _xlpm.mapCodes, _xlpm.mapType, ""), IF(_xlpm.codeType="F","F", IF(_xlpm.codeType="M", _xlfn.IFS( _xlpm.mid="AHU", "M-E1", AND(_xlpm.kw>=0.37, _xlpm.kw<=15), "M-A1", AND(_xlpm.kw>=18.5, _xlpm.kw<22), "M-A1", AND(_xlpm.kw>=22, _xlpm.kw<=37), "M-B1", AND(_xlpm.kw>=45, _xlpm.kw<=75), "M-B1", AND(_xlpm.kw>=90, _xlpm.kw<=110), "M-B1", AND(_xlpm.kw>110, _xlpm.kw<132), "M-C1", AND(_xlpm.kw>=132, _xlpm.kw<=200), "M-D1", _xlpm.kw>200, "M-E1", TRUE, "<review>" ), "<review>" ) ) )} -> F | F8: {=_xlfn.LET( _xlpm.tag, UPPER(TRIM(A8)), _xlpm.kw, N(C8), _xlpm.flc, N(D8), _xlpm.I_MCCB, 160, _xlpm.I_ACB, 630, _xlpm.tACB, "400V Air Circuit Breaker(ACB) Feeder Cubicle (per Dwg LV1)", _xlpm.tMCCB_HI, "400V MCCB Feeder Cubicle (I > 160A, per Dwg LV3)", _xlpm.tMCCB_LO, "400V MCCB Feeder Cubicle (I < 160A, per Dwg LV4)", _xlpm.tM_LV_DOL, "400V DOL Motor Starter Cubicle", _xlpm.parts, _xlfn.TEXTSPLIT(_xlpm.tag,"-"), _xlpm.mid, IF(COUNTA(_xlpm.parts)>=2, INDEX(_xlpm.parts,1,2), ""), _xlpm.mapCodes, {"AHU";"CWP";"EF";"ACWC";"ACCU";"EDH";"WWG";"WWP";"HD"}, _xlpm.mapType, {"M";"M";"M";"F";"F";"F";"F";"F";"F"}, _xlpm.codeType, _xlfn.XLOOKUP(_xlpm.mid, _xlpm.mapCodes, _xlpm.mapType, ""), _xlpm.motorClass, IF(_xlpm.codeType="M", _xlfn.IFS( _xlpm.mid="AHU", "M-E1", AND(_xlpm.kw>=0.37, _xlpm.kw<=15), "M-A1", AND(_xlpm.kw>=18.5, _xlpm.kw<22), "M-A1", AND(_xlpm.kw>=22, _xlpm.kw<=37), "M-B1", AND(_xlpm.kw>=45, _xlpm.kw<=75), "M-B1", AND(_xlpm.kw>=90, _xlpm.kw<=110), "M-B1", AND(_xlpm.kw>110, _xlpm.kw<132), "M-C1", AND(_xlpm.kw>=132, _xlpm.kw<=200), "M-D1", _xlpm.kw>200, "M-E1", TRUE, "<review>" ), "" ), _xlpm.FeederSel, IF(_xlpm.flc>=_xlpm.I_ACB, _xlpm.tACB, IF(_xlpm.flc>_xlpm.I_MCCB, _xlpm.tMCCB_HI, _xlpm.tMCCB_LO)), IF(_xlpm.codeType="F", _xlpm.FeederSel, IF(_xlpm.codeType="M", IF(_xlpm.motorClass="<review>", "<review>", _xlpm.tM_LV_DOL), "CHECK TAG CODE: "&_xlpm.mid ) ) )} -> 400V MCCB Feeder Cubicle (I < 160A, per Dwg LV4) | G8: {=_xlfn.LET( _xlpm.c, UPPER(TRIM(_81IK6100018[[#This Row],[Starter Type]])), _xlpm.kw, N(_81IK6100018[[#This Row],[RATED POWER]]), _xlpm.flc, N(_81IK6100018[[#This Row],[FULL LOAD CURRENT]]), _xlpm.feederType, IFERROR( _xlfn.IFS( _xlpm.c="M-A1", "M_A1", _xlpm.c="M-B1", "M_B1", _xlpm.c="M-C1", "M_C1", _xlpm.c="M-D1", "M_D1", _xlpm.c="M-E1", "M_E1", _xlpm.c="U", "UPS", _xlpm.c="F", "FEEDER", _xlpm.c="L", "LIGHT", _xlpm.c="H", "HEATER", ISNUMBER(SEARCH("ACB", _xlpm.c)), "ACB", ISNUMBER(SEARCH("I > 160A", _xlpm.c)), "MCCB_HI", ISNUMBER(SEARCH("I < 160A", _xlpm.c)), "MCCB_LO", ISNUMBER(SEARCH("3PH+N+PE", _xlpm.c)), "3PNPE", ISNUMBER(SEARCH("SCR", _xlpm.c)), "SCR", ISNUMBER(SEARCH("VSD", _xlpm.c)), "MCCB_VSD", ISNUMBER(SEARCH("FVNR", _xlpm.c)), "FVNR", TRUE, "OTHER" ), "OTHER" ), _xlpm.LowE, _xlfn.LAMBDA(_xlpm.a, IF(_xlpm.a<=50, "8E", IF(_xlpm.a<=100, "12E", "16E"))), _xlpm.HighE, _xlfn.LAMBDA(_xlpm.a, IF(_xlpm.a<=250, "16E", IF(_xlpm.a<=400, "24E", "36E"))), _xlpm.FeederE, IF(_xlpm.flc<=32, "8E/4", IF(_xlpm.flc<=160, _xlpm.LowE(_xlpm.flc), _xlpm.HighE(_xlpm.flc))), _xlfn.IFS( _xlpm.feederType="ACB", "72E", _xlpm.feederType="MCCB_LO", _xlpm.LowE(_xlpm.flc), _xlpm.feederType="MCCB_HI", _xlpm.HighE(_xlpm.flc), _xlpm.feederType="3PNPE", _xlpm.LowE(_xlpm.flc), _xlpm.feederType="SCR", IF(_xlpm.flc<=63, "8E", IF(_xlpm.flc<=125, "12E", IF(_xlpm.flc<=250, "24E", "36E"))), _xlpm.feederType="MCCB_VSD",_xlpm.HighE(_xlpm.flc), _xlpm.feederType="FVNR", IF(_xlpm.kw<=55, "16E", IF(_xlpm.kw<=90, "24E", "36E")), _xlpm.feederType="M_A1", IF(_xlpm.kw<=15, "8E/4", "8E"), _xlpm.feederType="M_B1", IF(_xlpm.kw<=37, "8E", "12E"), _xlpm.feederType="M_C1", IF(_xlpm.kw<132, "12E", "16E"), _xlpm.feederType="M_D1", "16E", _xlpm.feederType="M_E1", "24E", _xlpm.feederType="UPS", IF(_xlpm.flc<=50, "8E", IF(_xlpm.flc<=100, "12E", IF(_xlpm.flc<=250, "16E", IF(_xlpm.flc<=400, "24E", "36E")))), _xlpm.feederType="FEEDER", _xlpm.FeederE, _xlpm.feederType="LIGHT", _xlpm.FeederE, _xlpm.feederType="HEATER", _xlpm.FeederE, TRUE, "<review>" ) )} -> 8E | N8: M-E1 | O8: 400V DOL Motor Starter Cubicle | P8: 36E | Q8: =COUNTIFS($E$4:$E$18,N8,$F$4:$F$18,O8,$G$4:$G$18,P8) -> 0 | R8: =ROUNDUP(Q8*0.2,0) -> 0
A9: WH-ACCU-002 | B9: A | C9: 24.5 | D9: 38.812724 | E9: {=_xlfn.LET( _xlpm.tag, UPPER(TRIM(A9)), _xlpm.kw, N(C9), _xlpm.parts, _xlfn.TEXTSPLIT(_xlpm.tag,"-"), _xlpm.mid, IF(COUNTA(_xlpm.parts)>=2, INDEX(_xlpm.parts,1,2), ""), _xlpm.mapCodes, {"AHU";"CWP";"EF";"ACWC";"ACCU";"EDH";"WWG";"WWP";"HD"}, _xlpm.mapType, {"M";"M";"M";"F";"F";"F";"F";"F";"F"}, _xlpm.codeType, _xlfn.XLOOKUP(_xlpm.mid, _xlpm.mapCodes, _xlpm.mapType, ""), IF(_xlpm.codeType="F","F", IF(_xlpm.codeType="M", _xlfn.IFS( _xlpm.mid="AHU", "M-E1", AND(_xlpm.kw>=0.37, _xlpm.kw<=15), "M-A1", AND(_xlpm.kw>=18.5, _xlpm.kw<22), "M-A1", AND(_xlpm.kw>=22, _xlpm.kw<=37), "M-B1", AND(_xlpm.kw>=45, _xlpm.kw<=75), "M-B1", AND(_xlpm.kw>=90, _xlpm.kw<=110), "M-B1", AND(_xlpm.kw>110, _xlpm.kw<132), "M-C1", AND(_xlpm.kw>=132, _xlpm.kw<=200), "M-D1", _xlpm.kw>200, "M-E1", TRUE, "<review>" ), "<review>" ) ) )} -> F | F9: {=_xlfn.LET( _xlpm.tag, UPPER(TRIM(A9)), _xlpm.kw, N(C9), _xlpm.flc, N(D9), _xlpm.I_MCCB, 160, _xlpm.I_ACB, 630, _xlpm.tACB, "400V Air Circuit Breaker(ACB) Feeder Cubicle (per Dwg LV1)", _xlpm.tMCCB_HI, "400V MCCB Feeder Cubicle (I > 160A, per Dwg LV3)", _xlpm.tMCCB_LO, "400V MCCB Feeder Cubicle (I < 160A, per Dwg LV4)", _xlpm.tM_LV_DOL, "400V DOL Motor Starter Cubicle", _xlpm.parts, _xlfn.TEXTSPLIT(_xlpm.tag,"-"), _xlpm.mid, IF(COUNTA(_xlpm.parts)>=2, INDEX(_xlpm.parts,1,2), ""), _xlpm.mapCodes, {"AHU";"CWP";"EF";"ACWC";"ACCU";"EDH";"WWG";"WWP";"HD"}, _xlpm.mapType, {"M";"M";"M";"F";"F";"F";"F";"F";"F"}, _xlpm.codeType, _xlfn.XLOOKUP(_xlpm.mid, _xlpm.mapCodes, _xlpm.mapType, ""), _xlpm.motorClass, IF(_xlpm.codeType="M", _xlfn.IFS( _xlpm.mid="AHU", "M-E1", AND(_xlpm.kw>=0.37, _xlpm.kw<=15), "M-A1", AND(_xlpm.kw>=18.5, _xlpm.kw<22), "M-A1", AND(_xlpm.kw>=22, _xlpm.kw<=37), "M-B1", AND(_xlpm.kw>=45, _xlpm.kw<=75), "M-B1", AND(_xlpm.kw>=90, _xlpm.kw<=110), "M-B1", AND(_xlpm.kw>110, _xlpm.kw<132), "M-C1", AND(_xlpm.kw>=132, _xlpm.kw<=200), "M-D1", _xlpm.kw>200, "M-E1", TRUE, "<review>" ), "" ), _xlpm.FeederSel, IF(_xlpm.flc>=_xlpm.I_ACB, _xlpm.tACB, IF(_xlpm.flc>_xlpm.I_MCCB, _xlpm.tMCCB_HI, _xlpm.tMCCB_LO)), IF(_xlpm.codeType="F", _xlpm.FeederSel, IF(_xlpm.codeType="M", IF(_xlpm.motorClass="<review>", "<review>", _xlpm.tM_LV_DOL), "CHECK TAG CODE: "&_xlpm.mid ) ) )} -> 400V MCCB Feeder Cubicle (I < 160A, per Dwg LV4) | G9: {=_xlfn.LET( _xlpm.c, UPPER(TRIM(_81IK6100018[[#This Row],[Starter Type]])), _xlpm.kw, N(_81IK6100018[[#This Row],[RATED POWER]]), _xlpm.flc, N(_81IK6100018[[#This Row],[FULL LOAD CURRENT]]), _xlpm.feederType, IFERROR( _xlfn.IFS( _xlpm.c="M-A1", "M_A1", _xlpm.c="M-B1", "M_B1", _xlpm.c="M-C1", "M_C1", _xlpm.c="M-D1", "M_D1", _xlpm.c="M-E1", "M_E1", _xlpm.c="U", "UPS", _xlpm.c="F", "FEEDER", _xlpm.c="L", "LIGHT", _xlpm.c="H", "HEATER", ISNUMBER(SEARCH("ACB", _xlpm.c)), "ACB", ISNUMBER(SEARCH("I > 160A", _xlpm.c)), "MCCB_HI", ISNUMBER(SEARCH("I < 160A", _xlpm.c)), "MCCB_LO", ISNUMBER(SEARCH("3PH+N+PE", _xlpm.c)), "3PNPE", ISNUMBER(SEARCH("SCR", _xlpm.c)), "SCR", ISNUMBER(SEARCH("VSD", _xlpm.c)), "MCCB_VSD", ISNUMBER(SEARCH("FVNR", _xlpm.c)), "FVNR", TRUE, "OTHER" ), "OTHER" ), _xlpm.LowE, _xlfn.LAMBDA(_xlpm.a, IF(_xlpm.a<=50, "8E", IF(_xlpm.a<=100, "12E", "16E"))), _xlpm.HighE, _xlfn.LAMBDA(_xlpm.a, IF(_xlpm.a<=250, "16E", IF(_xlpm.a<=400, "24E", "36E"))), _xlpm.FeederE, IF(_xlpm.flc<=32, "8E/4", IF(_xlpm.flc<=160, _xlpm.LowE(_xlpm.flc), _xlpm.HighE(_xlpm.flc))), _xlfn.IFS( _xlpm.feederType="ACB", "72E", _xlpm.feederType="MCCB_LO", _xlpm.LowE(_xlpm.flc), _xlpm.feederType="MCCB_HI", _xlpm.HighE(_xlpm.flc), _xlpm.feederType="3PNPE", _xlpm.LowE(_xlpm.flc), _xlpm.feederType="SCR", IF(_xlpm.flc<=63, "8E", IF(_xlpm.flc<=125, "12E", IF(_xlpm.flc<=250, "24E", "36E"))), _xlpm.feederType="MCCB_VSD",_xlpm.HighE(_xlpm.flc), _xlpm.feederType="FVNR", IF(_xlpm.kw<=55, "16E", IF(_xlpm.kw<=90, "24E", "36E")), _xlpm.feederType="M_A1", IF(_xlpm.kw<=15, "8E/4", "8E"), _xlpm.feederType="M_B1", IF(_xlpm.kw<=37, "8E", "12E"), _xlpm.feederType="M_C1", IF(_xlpm.kw<132, "12E", "16E"), _xlpm.feederType="M_D1", "16E", _xlpm.feederType="M_E1", "24E", _xlpm.feederType="UPS", IF(_xlpm.flc<=50, "8E", IF(_xlpm.flc<=100, "12E", IF(_xlpm.flc<=250, "16E", IF(_xlpm.flc<=400, "24E", "36E")))), _xlpm.feederType="FEEDER", _xlpm.FeederE, _xlpm.feederType="LIGHT", _xlpm.FeederE, _xlpm.feederType="HEATER", _xlpm.FeederE, TRUE, "<review>" ) )} -> 8E | N9: F | O9: 400V MCCB Feeder Cubicle (I > 160A, per Dwg LV3) | P9: 16E | Q9: =COUNTIFS($E$4:$E$18,N9,$F$4:$F$18,O9,$G$4:$G$18,P9) -> 0 | R9: =ROUNDUP(Q9*0.2,0) -> 0
A10: WH-EF-001 | B10: A | C10: 0.37 | D10: 1.0193936 | E10: {=_xlfn.LET( _xlpm.tag, UPPER(TRIM(A10)), _xlpm.kw, N(C10), _xlpm.parts, _xlfn.TEXTSPLIT(_xlpm.tag,"-"), _xlpm.mid, IF(COUNTA(_xlpm.parts)>=2, INDEX(_xlpm.parts,1,2), ""), _xlpm.mapCodes, {"AHU";"CWP";"EF";"ACWC";"ACCU";"EDH";"WWG";"WWP";"HD"}, _xlpm.mapType, {"M";"M";"M";"F";"F";"F";"F";"F";"F"}, _xlpm.codeType, _xlfn.XLOOKUP(_xlpm.mid, _xlpm.mapCodes, _xlpm.mapType, ""), IF(_xlpm.codeType="F","F", IF(_xlpm.codeType="M", _xlfn.IFS( _xlpm.mid="AHU", "M-E1", AND(_xlpm.kw>=0.37, _xlpm.kw<=15), "M-A1", AND(_xlpm.kw>=18.5, _xlpm.kw<22), "M-A1", AND(_xlpm.kw>=22, _xlpm.kw<=37), "M-B1", AND(_xlpm.kw>=45, _xlpm.kw<=75), "M-B1", AND(_xlpm.kw>=90, _xlpm.kw<=110), "M-B1", AND(_xlpm.kw>110, _xlpm.kw<132), "M-C1", AND(_xlpm.kw>=132, _xlpm.kw<=200), "M-D1", _xlpm.kw>200, "M-E1", TRUE, "<review>" ), "<review>" ) ) )} -> M-A1 | F10: {=_xlfn.LET( _xlpm.tag, UPPER(TRIM(A10)), _xlpm.kw, N(C10), _xlpm.flc, N(D10), _xlpm.I_MCCB, 160, _xlpm.I_ACB, 630, _xlpm.tACB, "400V Air Circuit Breaker(ACB) Feeder Cubicle (per Dwg LV1)", _xlpm.tMCCB_HI, "400V MCCB Feeder Cubicle (I > 160A, per Dwg LV3)", _xlpm.tMCCB_LO, "400V MCCB Feeder Cubicle (I < 160A, per Dwg LV4)", _xlpm.tM_LV_DOL, "400V DOL Motor Starter Cubicle", _xlpm.parts, _xlfn.TEXTSPLIT(_xlpm.tag,"-"), _xlpm.mid, IF(COUNTA(_xlpm.parts)>=2, INDEX(_xlpm.parts,1,2), ""), _xlpm.mapCodes, {"AHU";"CWP";"EF";"ACWC";"ACCU";"EDH";"WWG";"WWP";"HD"}, _xlpm.mapType, {"M";"M";"M";"F";"F";"F";"F";"F";"F"}, _xlpm.codeType, _xlfn.XLOOKUP(_xlpm.mid, _xlpm.mapCodes, _xlpm.mapType, ""), _xlpm.motorClass, IF(_xlpm.codeType="M", _xlfn.IFS( _xlpm.mid="AHU", "M-E1", AND(_xlpm.kw>=0.37, _xlpm.kw<=15), "M-A1", AND(_xlpm.kw>=18.5, _xlpm.kw<22), "M-A1", AND(_xlpm.kw>=22, _xlpm.kw<=37), "M-B1", AND(_xlpm.kw>=45, _xlpm.kw<=75), "M-B1", AND(_xlpm.kw>=90, _xlpm.kw<=110), "M-B1", AND(_xlpm.kw>110, _xlpm.kw<132), "M-C1", AND(_xlpm.kw>=132, _xlpm.kw<=200), "M-D1", _xlpm.kw>200, "M-E1", TRUE, "<review>" ), "" ), _xlpm.FeederSel, IF(_xlpm.flc>=_xlpm.I_ACB, _xlpm.tACB, IF(_xlpm.flc>_xlpm.I_MCCB, _xlpm.tMCCB_HI, _xlpm.tMCCB_LO)), IF(_xlpm.codeType="F", _xlpm.FeederSel, IF(_xlpm.codeType="M", IF(_xlpm.motorClass="<review>", "<review>", _xlpm.tM_LV_DOL), "CHECK TAG CODE: "&_xlpm.mid ) ) )} -> 400V DOL Motor Starter Cubicle | G10: {=_xlfn.LET( _xlpm.c, UPPER(TRIM(_81IK6100018[[#This Row],[Starter Type]])), _xlpm.kw, N(_81IK6100018[[#This Row],[RATED POWER]]), _xlpm.flc, N(_81IK6100018[[#This Row],[FULL LOAD CURRENT]]), _xlpm.feederType, IFERROR( _xlfn.IFS( _xlpm.c="M-A1", "M_A1", _xlpm.c="M-B1", "M_B1", _xlpm.c="M-C1", "M_C1", _xlpm.c="M-D1", "M_D1", _xlpm.c="M-E1", "M_E1", _xlpm.c="U", "UPS", _xlpm.c="F", "FEEDER", _xlpm.c="L", "LIGHT", _xlpm.c="H", "HEATER", ISNUMBER(SEARCH("ACB", _xlpm.c)), "ACB", ISNUMBER(SEARCH("I > 160A", _xlpm.c)), "MCCB_HI", ISNUMBER(SEARCH("I < 160A", _xlpm.c)), "MCCB_LO", ISNUMBER(SEARCH("3PH+N+PE", _xlpm.c)), "3PNPE", ISNUMBER(SEARCH("SCR", _xlpm.c)), "SCR", ISNUMBER(SEARCH("VSD", _xlpm.c)), "MCCB_VSD", ISNUMBER(SEARCH("FVNR", _xlpm.c)), "FVNR", TRUE, "OTHER" ), "OTHER" ), _xlpm.LowE, _xlfn.LAMBDA(_xlpm.a, IF(_xlpm.a<=50, "8E", IF(_xlpm.a<=100, "12E", "16E"))), _xlpm.HighE, _xlfn.LAMBDA(_xlpm.a, IF(_xlpm.a<=250, "16E", IF(_xlpm.a<=400, "24E", "36E"))), _xlpm.FeederE, IF(_xlpm.flc<=32, "8E/4", IF(_xlpm.flc<=160, _xlpm.LowE(_xlpm.flc), _xlpm.HighE(_xlpm.flc))), _xlfn.IFS( _xlpm.feederType="ACB", "72E", _xlpm.feederType="MCCB_LO", _xlpm.LowE(_xlpm.flc), _xlpm.feederType="MCCB_HI", _xlpm.HighE(_xlpm.flc), _xlpm.feederType="3PNPE", _xlpm.LowE(_xlpm.flc), _xlpm.feederType="SCR", IF(_xlpm.flc<=63, "8E", IF(_xlpm.flc<=125, "12E", IF(_xlpm.flc<=250, "24E", "36E"))), _xlpm.feederType="MCCB_VSD",_xlpm.HighE(_xlpm.flc), _xlpm.feederType="FVNR", IF(_xlpm.kw<=55, "16E", IF(_xlpm.kw<=90, "24E", "36E")), _xlpm.feederType="M_A1", IF(_xlpm.kw<=15, "8E/4", "8E"), _xlpm.feederType="M_B1", IF(_xlpm.kw<=37, "8E", "12E"), _xlpm.feederType="M_C1", IF(_xlpm.kw<132, "12E", "16E"), _xlpm.feederType="M_D1", "16E", _xlpm.feederType="M_E1", "24E", _xlpm.feederType="UPS", IF(_xlpm.flc<=50, "8E", IF(_xlpm.flc<=100, "12E", IF(_xlpm.flc<=250, "16E", IF(_xlpm.flc<=400, "24E", "36E")))), _xlpm.feederType="FEEDER", _xlpm.FeederE, _xlpm.feederType="LIGHT", _xlpm.FeederE, _xlpm.feederType="HEATER", _xlpm.FeederE, TRUE, "<review>" ) )} -> 8E/4 | N10: F | O10: 400V MCCB Feeder Cubicle (I < 160A, per Dwg LV4) | P10: 16E | Q10: =COUNTIFS($E$4:$E$18,N10,$F$4:$F$18,O10,$G$4:$G$18,P10) -> 1 | R10: =ROUNDUP(Q10*0.2,0) -> 1
A11: WH-EF-002 | B11: A | C11: 0.37 | D11: 0.58615134 | E11: {=_xlfn.LET( _xlpm.tag, UPPER(TRIM(A11)), _xlpm.kw, N(C11), _xlpm.parts, _xlfn.TEXTSPLIT(_xlpm.tag,"-"), _xlpm.mid, IF(COUNTA(_xlpm.parts)>=2, INDEX(_xlpm.parts,1,2), ""), _xlpm.mapCodes, {"AHU";"CWP";"EF";"ACWC";"ACCU";"EDH";"WWG";"WWP";"HD"}, _xlpm.mapType, {"M";"M";"M";"F";"F";"F";"F";"F";"F"}, _xlpm.codeType, _xlfn.XLOOKUP(_xlpm.mid, _xlpm.mapCodes, _xlpm.mapType, ""), IF(_xlpm.codeType="F","F", IF(_xlpm.codeType="M", _xlfn.IFS( _xlpm.mid="AHU", "M-E1", AND(_xlpm.kw>=0.37, _xlpm.kw<=15), "M-A1", AND(_xlpm.kw>=18.5, _xlpm.kw<22), "M-A1", AND(_xlpm.kw>=22, _xlpm.kw<=37), "M-B1", AND(_xlpm.kw>=45, _xlpm.kw<=75), "M-B1", AND(_xlpm.kw>=90, _xlpm.kw<=110), "M-B1", AND(_xlpm.kw>110, _xlpm.kw<132), "M-C1", AND(_xlpm.kw>=132, _xlpm.kw<=200), "M-D1", _xlpm.kw>200, "M-E1", TRUE, "<review>" ), "<review>" ) ) )} -> M-A1 | F11: {=_xlfn.LET( _xlpm.tag, UPPER(TRIM(A11)), _xlpm.kw, N(C11), _xlpm.flc, N(D11), _xlpm.I_MCCB, 160, _xlpm.I_ACB, 630, _xlpm.tACB, "400V Air Circuit Breaker(ACB) Feeder Cubicle (per Dwg LV1)", _xlpm.tMCCB_HI, "400V MCCB Feeder Cubicle (I > 160A, per Dwg LV3)", _xlpm.tMCCB_LO, "400V MCCB Feeder Cubicle (I < 160A, per Dwg LV4)", _xlpm.tM_LV_DOL, "400V DOL Motor Starter Cubicle", _xlpm.parts, _xlfn.TEXTSPLIT(_xlpm.tag,"-"), _xlpm.mid, IF(COUNTA(_xlpm.parts)>=2, INDEX(_xlpm.parts,1,2), ""), _xlpm.mapCodes, {"AHU";"CWP";"EF";"ACWC";"ACCU";"EDH";"WWG";"WWP";"HD"}, _xlpm.mapType, {"M";"M";"M";"F";"F";"F";"F";"F";"F"}, _xlpm.codeType, _xlfn.XLOOKUP(_xlpm.mid, _xlpm.mapCodes, _xlpm.mapType, ""), _xlpm.motorClass, IF(_xlpm.codeType="M", _xlfn.IFS( _xlpm.mid="AHU", "M-E1", AND(_xlpm.kw>=0.37, _xlpm.kw<=15), "M-A1", AND(_xlpm.kw>=18.5, _xlpm.kw<22), "M-A1", AND(_xlpm.kw>=22, _xlpm.kw<=37), "M-B1", AND(_xlpm.kw>=45, _xlpm.kw<=75), "M-B1", AND(_xlpm.kw>=90, _xlpm.kw<=110), "M-B1", AND(_xlpm.kw>110, _xlpm.kw<132), "M-C1", AND(_xlpm.kw>=132, _xlpm.kw<=200), "M-D1", _xlpm.kw>200, "M-E1", TRUE, "<review>" ), "" ), _xlpm.FeederSel, IF(_xlpm.flc>=_xlpm.I_ACB, _xlpm.tACB, IF(_xlpm.flc>_xlpm.I_MCCB, _xlpm.tMCCB_HI, _xlpm.tMCCB_LO)), IF(_xlpm.codeType="F", _xlpm.FeederSel, IF(_xlpm.codeType="M", IF(_xlpm.motorClass="<review>", "<review>", _xlpm.tM_LV_DOL), "CHECK TAG CODE: "&_xlpm.mid ) ) )} -> 400V DOL Motor Starter Cubicle | G11: {=_xlfn.LET( _xlpm.c, UPPER(TRIM(_81IK6100018[[#This Row],[Starter Type]])), _xlpm.kw, N(_81IK6100018[[#This Row],[RATED POWER]]), _xlpm.flc, N(_81IK6100018[[#This Row],[FULL LOAD CURRENT]]), _xlpm.feederType, IFERROR( _xlfn.IFS( _xlpm.c="M-A1", "M_A1", _xlpm.c="M-B1", "M_B1", _xlpm.c="M-C1", "M_C1", _xlpm.c="M-D1", "M_D1", _xlpm.c="M-E1", "M_E1", _xlpm.c="U", "UPS", _xlpm.c="F", "FEEDER", _xlpm.c="L", "LIGHT", _xlpm.c="H", "HEATER", ISNUMBER(SEARCH("ACB", _xlpm.c)), "ACB", ISNUMBER(SEARCH("I > 160A", _xlpm.c)), "MCCB_HI", ISNUMBER(SEARCH("I < 160A", _xlpm.c)), "MCCB_LO", ISNUMBER(SEARCH("3PH+N+PE", _xlpm.c)), "3PNPE", ISNUMBER(SEARCH("SCR", _xlpm.c)), "SCR", ISNUMBER(SEARCH("VSD", _xlpm.c)), "MCCB_VSD", ISNUMBER(SEARCH("FVNR", _xlpm.c)), "FVNR", TRUE, "OTHER" ), "OTHER" ), _xlpm.LowE, _xlfn.LAMBDA(_xlpm.a, IF(_xlpm.a<=50, "8E", IF(_xlpm.a<=100, "12E", "16E"))), _xlpm.HighE, _xlfn.LAMBDA(_xlpm.a, IF(_xlpm.a<=250, "16E", IF(_xlpm.a<=400, "24E", "36E"))), _xlpm.FeederE, IF(_xlpm.flc<=32, "8E/4", IF(_xlpm.flc<=160, _xlpm.LowE(_xlpm.flc), _xlpm.HighE(_xlpm.flc))), _xlfn.IFS( _xlpm.feederType="ACB", "72E", _xlpm.feederType="MCCB_LO", _xlpm.LowE(_xlpm.flc), _xlpm.feederType="MCCB_HI", _xlpm.HighE(_xlpm.flc), _xlpm.feederType="3PNPE", _xlpm.LowE(_xlpm.flc), _xlpm.feederType="SCR", IF(_xlpm.flc<=63, "8E", IF(_xlpm.flc<=125, "12E", IF(_xlpm.flc<=250, "24E", "36E"))), _xlpm.feederType="MCCB_VSD",_xlpm.HighE(_xlpm.flc), _xlpm.feederType="FVNR", IF(_xlpm.kw<=55, "16E", IF(_xlpm.kw<=90, "24E", "36E")), _xlpm.feederType="M_A1", IF(_xlpm.kw<=15, "8E/4", "8E"), _xlpm.feederType="M_B1", IF(_xlpm.kw<=37, "8E", "12E"), _xlpm.feederType="M_C1", IF(_xlpm.kw<132, "12E", "16E"), _xlpm.feederType="M_D1", "16E", _xlpm.feederType="M_E1", "24E", _xlpm.feederType="UPS", IF(_xlpm.flc<=50, "8E", IF(_xlpm.flc<=100, "12E", IF(_xlpm.flc<=250, "16E", IF(_xlpm.flc<=400, "24E", "36E")))), _xlpm.feederType="FEEDER", _xlpm.FeederE, _xlpm.feederType="LIGHT", _xlpm.FeederE, _xlpm.feederType="HEATER", _xlpm.FeederE, TRUE, "<review>" ) )} -> 8E/4 | N11: F | O11: 400V MCCB Feeder Cubicle (I < 160A, per Dwg LV4) | P11: 12E | Q11: =COUNTIFS($E$4:$E$18,N11,$F$4:$F$18,O11,$G$4:$G$18,P11) -> 0 | R11: =ROUNDUP(Q11*0.2,0) -> 0
A12: WH-EF-003 | B12: A | C12: 0.37 | D12: 0.58615134 | E12: {=_xlfn.LET( _xlpm.tag, UPPER(TRIM(A12)), _xlpm.kw, N(C12), _xlpm.parts, _xlfn.TEXTSPLIT(_xlpm.tag,"-"), _xlpm.mid, IF(COUNTA(_xlpm.parts)>=2, INDEX(_xlpm.parts,1,2), ""), _xlpm.mapCodes, {"AHU";"CWP";"EF";"ACWC";"ACCU";"EDH";"WWG";"WWP";"HD"}, _xlpm.mapType, {"M";"M";"M";"F";"F";"F";"F";"F";"F"}, _xlpm.codeType, _xlfn.XLOOKUP(_xlpm.mid, _xlpm.mapCodes, _xlpm.mapType, ""), IF(_xlpm.codeType="F","F", IF(_xlpm.codeType="M", _xlfn.IFS( _xlpm.mid="AHU", "M-E1", AND(_xlpm.kw>=0.37, _xlpm.kw<=15), "M-A1", AND(_xlpm.kw>=18.5, _xlpm.kw<22), "M-A1", AND(_xlpm.kw>=22, _xlpm.kw<=37), "M-B1", AND(_xlpm.kw>=45, _xlpm.kw<=75), "M-B1", AND(_xlpm.kw>=90, _xlpm.kw<=110), "M-B1", AND(_xlpm.kw>110, _xlpm.kw<132), "M-C1", AND(_xlpm.kw>=132, _xlpm.kw<=200), "M-D1", _xlpm.kw>200, "M-E1", TRUE, "<review>" ), "<review>" ) ) )} -> M-A1 | F12: {=_xlfn.LET( _xlpm.tag, UPPER(TRIM(A12)), _xlpm.kw, N(C12), _xlpm.flc, N(D12), _xlpm.I_MCCB, 160, _xlpm.I_ACB, 630, _xlpm.tACB, "400V Air Circuit Breaker(ACB) Feeder Cubicle (per Dwg LV1)", _xlpm.tMCCB_HI, "400V MCCB Feeder Cubicle (I > 160A, per Dwg LV3)", _xlpm.tMCCB_LO, "400V MCCB Feeder Cubicle (I < 160A, per Dwg LV4)", _xlpm.tM_LV_DOL, "400V DOL Motor Starter Cubicle", _xlpm.parts, _xlfn.TEXTSPLIT(_xlpm.tag,"-"), _xlpm.mid, IF(COUNTA(_xlpm.parts)>=2, INDEX(_xlpm.parts,1,2), ""), _xlpm.mapCodes, {"AHU";"CWP";"EF";"ACWC";"ACCU";"EDH";"WWG";"WWP";"HD"}, _xlpm.mapType, {"M";"M";"M";"F";"F";"F";"F";"F";"F"}, _xlpm.codeType, _xlfn.XLOOKUP(_xlpm.mid, _xlpm.mapCodes, _xlpm.mapType, ""), _xlpm.motorClass, IF(_xlpm.codeType="M", _xlfn.IFS( _xlpm.mid="AHU", "M-E1", AND(_xlpm.kw>=0.37, _xlpm.kw<=15), "M-A1", AND(_xlpm.kw>=18.5, _xlpm.kw<22), "M-A1", AND(_xlpm.kw>=22, _xlpm.kw<=37), "M-B1", AND(_xlpm.kw>=45, _xlpm.kw<=75), "M-B1", AND(_xlpm.kw>=90, _xlpm.kw<=110), "M-B1", AND(_xlpm.kw>110, _xlpm.kw<132), "M-C1", AND(_xlpm.kw>=132, _xlpm.kw<=200), "M-D1", _xlpm.kw>200, "M-E1", TRUE, "<review>" ), "" ), _xlpm.FeederSel, IF(_xlpm.flc>=_xlpm.I_ACB, _xlpm.tACB, IF(_xlpm.flc>_xlpm.I_MCCB, _xlpm.tMCCB_HI, _xlpm.tMCCB_LO)), IF(_xlpm.codeType="F", _xlpm.FeederSel, IF(_xlpm.codeType="M", IF(_xlpm.motorClass="<review>", "<review>", _xlpm.tM_LV_DOL), "CHECK TAG CODE: "&_xlpm.mid ) ) )} -> 400V DOL Motor Starter Cubicle | G12: {=_xlfn.LET( _xlpm.c, UPPER(TRIM(_81IK6100018[[#This Row],[Starter Type]])), _xlpm.kw, N(_81IK6100018[[#This Row],[RATED POWER]]), _xlpm.flc, N(_81IK6100018[[#This Row],[FULL LOAD CURRENT]]), _xlpm.feederType, IFERROR( _xlfn.IFS( _xlpm.c="M-A1", "M_A1", _xlpm.c="M-B1", "M_B1", _xlpm.c="M-C1", "M_C1", _xlpm.c="M-D1", "M_D1", _xlpm.c="M-E1", "M_E1", _xlpm.c="U", "UPS", _xlpm.c="F", "FEEDER", _xlpm.c="L", "LIGHT", _xlpm.c="H", "HEATER", ISNUMBER(SEARCH("ACB", _xlpm.c)), "ACB", ISNUMBER(SEARCH("I > 160A", _xlpm.c)), "MCCB_HI", ISNUMBER(SEARCH("I < 160A", _xlpm.c)), "MCCB_LO", ISNUMBER(SEARCH("3PH+N+PE", _xlpm.c)), "3PNPE", ISNUMBER(SEARCH("SCR", _xlpm.c)), "SCR", ISNUMBER(SEARCH("VSD", _xlpm.c)), "MCCB_VSD", ISNUMBER(SEARCH("FVNR", _xlpm.c)), "FVNR", TRUE, "OTHER" ), "OTHER" ), _xlpm.LowE, _xlfn.LAMBDA(_xlpm.a, IF(_xlpm.a<=50, "8E", IF(_xlpm.a<=100, "12E", "16E"))), _xlpm.HighE, _xlfn.LAMBDA(_xlpm.a, IF(_xlpm.a<=250, "16E", IF(_xlpm.a<=400, "24E", "36E"))), _xlpm.FeederE, IF(_xlpm.flc<=32, "8E/4", IF(_xlpm.flc<=160, _xlpm.LowE(_xlpm.flc), _xlpm.HighE(_xlpm.flc))), _xlfn.IFS( _xlpm.feederType="ACB", "72E", _xlpm.feederType="MCCB_LO", _xlpm.LowE(_xlpm.flc), _xlpm.feederType="MCCB_HI", _xlpm.HighE(_xlpm.flc), _xlpm.feederType="3PNPE", _xlpm.LowE(_xlpm.flc), _xlpm.feederType="SCR", IF(_xlpm.flc<=63, "8E", IF(_xlpm.flc<=125, "12E", IF(_xlpm.flc<=250, "24E", "36E"))), _xlpm.feederType="MCCB_VSD",_xlpm.HighE(_xlpm.flc), _xlpm.feederType="FVNR", IF(_xlpm.kw<=55, "16E", IF(_xlpm.kw<=90, "24E", "36E")), _xlpm.feederType="M_A1", IF(_xlpm.kw<=15, "8E/4", "8E"), _xlpm.feederType="M_B1", IF(_xlpm.kw<=37, "8E", "12E"), _xlpm.feederType="M_C1", IF(_xlpm.kw<132, "12E", "16E"), _xlpm.feederType="M_D1", "16E", _xlpm.feederType="M_E1", "24E", _xlpm.feederType="UPS", IF(_xlpm.flc<=50, "8E", IF(_xlpm.flc<=100, "12E", IF(_xlpm.flc<=250, "16E", IF(_xlpm.flc<=400, "24E", "36E")))), _xlpm.feederType="FEEDER", _xlpm.FeederE, _xlpm.feederType="LIGHT", _xlpm.FeederE, _xlpm.feederType="HEATER", _xlpm.FeederE, TRUE, "<review>" ) )} -> 8E/4 | N12: H | O12: 400V SCR-Controlled Heater Feeder Cubicle (per Dwg LV8) | P12: 16E | Q12: =COUNTIFS($E$4:$E$18,N12,$F$4:$F$18,O12,$G$4:$G$18,P12) -> 0 | R12: =ROUNDUP(Q12*0.2,0) -> 0
A13: WH-EDH-001 | B13: A | C13: 1.32 | D13: 2.0911345 | E13: {=_xlfn.LET( _xlpm.tag, UPPER(TRIM(A13)), _xlpm.kw, N(C13), _xlpm.parts, _xlfn.TEXTSPLIT(_xlpm.tag,"-"), _xlpm.mid, IF(COUNTA(_xlpm.parts)>=2, INDEX(_xlpm.parts,1,2), ""), _xlpm.mapCodes, {"AHU";"CWP";"EF";"ACWC";"ACCU";"EDH";"WWG";"WWP";"HD"}, _xlpm.mapType, {"M";"M";"M";"F";"F";"F";"F";"F";"F"}, _xlpm.codeType, _xlfn.XLOOKUP(_xlpm.mid, _xlpm.mapCodes, _xlpm.mapType, ""), IF(_xlpm.codeType="F","F", IF(_xlpm.codeType="M", _xlfn.IFS( _xlpm.mid="AHU", "M-E1", AND(_xlpm.kw>=0.37, _xlpm.kw<=15), "M-A1", AND(_xlpm.kw>=18.5, _xlpm.kw<22), "M-A1", AND(_xlpm.kw>=22, _xlpm.kw<=37), "M-B1", AND(_xlpm.kw>=45, _xlpm.kw<=75), "M-B1", AND(_xlpm.kw>=90, _xlpm.kw<=110), "M-B1", AND(_xlpm.kw>110, _xlpm.kw<132), "M-C1", AND(_xlpm.kw>=132, _xlpm.kw<=200), "M-D1", _xlpm.kw>200, "M-E1", TRUE, "<review>" ), "<review>" ) ) )} -> F | F13: {=_xlfn.LET( _xlpm.tag, UPPER(TRIM(A13)), _xlpm.kw, N(C13), _xlpm.flc, N(D13), _xlpm.I_MCCB, 160, _xlpm.I_ACB, 630, _xlpm.tACB, "400V Air Circuit Breaker(ACB) Feeder Cubicle (per Dwg LV1)", _xlpm.tMCCB_HI, "400V MCCB Feeder Cubicle (I > 160A, per Dwg LV3)", _xlpm.tMCCB_LO, "400V MCCB Feeder Cubicle (I < 160A, per Dwg LV4)", _xlpm.tM_LV_DOL, "400V DOL Motor Starter Cubicle", _xlpm.parts, _xlfn.TEXTSPLIT(_xlpm.tag,"-"), _xlpm.mid, IF(COUNTA(_xlpm.parts)>=2, INDEX(_xlpm.parts,1,2), ""), _xlpm.mapCodes, {"AHU";"CWP";"EF";"ACWC";"ACCU";"EDH";"WWG";"WWP";"HD"}, _xlpm.mapType, {"M";"M";"M";"F";"F";"F";"F";"F";"F"}, _xlpm.codeType, _xlfn.XLOOKUP(_xlpm.mid, _xlpm.mapCodes, _xlpm.mapType, ""), _xlpm.motorClass, IF(_xlpm.codeType="M", _xlfn.IFS( _xlpm.mid="AHU", "M-E1", AND(_xlpm.kw>=0.37, _xlpm.kw<=15), "M-A1", AND(_xlpm.kw>=18.5, _xlpm.kw<22), "M-A1", AND(_xlpm.kw>=22, _xlpm.kw<=37), "M-B1", AND(_xlpm.kw>=45, _xlpm.kw<=75), "M-B1", AND(_xlpm.kw>=90, _xlpm.kw<=110), "M-B1", AND(_xlpm.kw>110, _xlpm.kw<132), "M-C1", AND(_xlpm.kw>=132, _xlpm.kw<=200), "M-D1", _xlpm.kw>200, "M-E1", TRUE, "<review>" ), "" ), _xlpm.FeederSel, IF(_xlpm.flc>=_xlpm.I_ACB, _xlpm.tACB, IF(_xlpm.flc>_xlpm.I_MCCB, _xlpm.tMCCB_HI, _xlpm.tMCCB_LO)), IF(_xlpm.codeType="F", _xlpm.FeederSel, IF(_xlpm.codeType="M", IF(_xlpm.motorClass="<review>", "<review>", _xlpm.tM_LV_DOL), "CHECK TAG CODE: "&_xlpm.mid ) ) )} -> 400V MCCB Feeder Cubicle (I < 160A, per Dwg LV4) | G13: {=_xlfn.LET( _xlpm.c, UPPER(TRIM(_81IK6100018[[#This Row],[Starter Type]])), _xlpm.kw, N(_81IK6100018[[#This Row],[RATED POWER]]), _xlpm.flc, N(_81IK6100018[[#This Row],[FULL LOAD CURRENT]]), _xlpm.feederType, IFERROR( _xlfn.IFS( _xlpm.c="M-A1", "M_A1", _xlpm.c="M-B1", "M_B1", _xlpm.c="M-C1", "M_C1", _xlpm.c="M-D1", "M_D1", _xlpm.c="M-E1", "M_E1", _xlpm.c="U", "UPS", _xlpm.c="F", "FEEDER", _xlpm.c="L", "LIGHT", _xlpm.c="H", "HEATER", ISNUMBER(SEARCH("ACB", _xlpm.c)), "ACB", ISNUMBER(SEARCH("I > 160A", _xlpm.c)), "MCCB_HI", ISNUMBER(SEARCH("I < 160A", _xlpm.c)), "MCCB_LO", ISNUMBER(SEARCH("3PH+N+PE", _xlpm.c)), "3PNPE", ISNUMBER(SEARCH("SCR", _xlpm.c)), "SCR", ISNUMBER(SEARCH("VSD", _xlpm.c)), "MCCB_VSD", ISNUMBER(SEARCH("FVNR", _xlpm.c)), "FVNR", TRUE, "OTHER" ), "OTHER" ), _xlpm.LowE, _xlfn.LAMBDA(_xlpm.a, IF(_xlpm.a<=50, "8E", IF(_xlpm.a<=100, "12E", "16E"))), _xlpm.HighE, _xlfn.LAMBDA(_xlpm.a, IF(_xlpm.a<=250, "16E", IF(_xlpm.a<=400, "24E", "36E"))), _xlpm.FeederE, IF(_xlpm.flc<=32, "8E/4", IF(_xlpm.flc<=160, _xlpm.LowE(_xlpm.flc), _xlpm.HighE(_xlpm.flc))), _xlfn.IFS( _xlpm.feederType="ACB", "72E", _xlpm.feederType="MCCB_LO", _xlpm.LowE(_xlpm.flc), _xlpm.feederType="MCCB_HI", _xlpm.HighE(_xlpm.flc), _xlpm.feederType="3PNPE", _xlpm.LowE(_xlpm.flc), _xlpm.feederType="SCR", IF(_xlpm.flc<=63, "8E", IF(_xlpm.flc<=125, "12E", IF(_xlpm.flc<=250, "24E", "36E"))), _xlpm.feederType="MCCB_VSD",_xlpm.HighE(_xlpm.flc), _xlpm.feederType="FVNR", IF(_xlpm.kw<=55, "16E", IF(_xlpm.kw<=90, "24E", "36E")), _xlpm.feederType="M_A1", IF(_xlpm.kw<=15, "8E/4", "8E"), _xlpm.feederType="M_B1", IF(_xlpm.kw<=37, "8E", "12E"), _xlpm.feederType="M_C1", IF(_xlpm.kw<132, "12E", "16E"), _xlpm.feederType="M_D1", "16E", _xlpm.feederType="M_E1", "24E", _xlpm.feederType="UPS", IF(_xlpm.flc<=50, "8E", IF(_xlpm.flc<=100, "12E", IF(_xlpm.flc<=250, "16E", IF(_xlpm.flc<=400, "24E", "36E")))), _xlpm.feederType="FEEDER", _xlpm.FeederE, _xlpm.feederType="LIGHT", _xlpm.FeederE, _xlpm.feederType="HEATER", _xlpm.FeederE, TRUE, "<review>" ) )} -> 8E/4 | N13: M-B1 | O13: 400V DOL Motor Starter Cubicle | P13: 24E | Q13: =COUNTIFS($E$4:$E$18,N13,$F$4:$F$18,O13,$G$4:$G$18,P13) -> 0 | R13: =ROUNDUP(Q13*0.2,0) -> 0
A14: WH-EDH-002 | B14: A | C14: 1.1 | D14: 1.7426121 | E14: {=_xlfn.LET( _xlpm.tag, UPPER(TRIM(A14)), _xlpm.kw, N(C14), _xlpm.parts, _xlfn.TEXTSPLIT(_xlpm.tag,"-"), _xlpm.mid, IF(COUNTA(_xlpm.parts)>=2, INDEX(_xlpm.parts,1,2), ""), _xlpm.mapCodes, {"AHU";"CWP";"EF";"ACWC";"ACCU";"EDH";"WWG";"WWP";"HD"}, _xlpm.mapType, {"M";"M";"M";"F";"F";"F";"F";"F";"F"}, _xlpm.codeType, _xlfn.XLOOKUP(_xlpm.mid, _xlpm.mapCodes, _xlpm.mapType, ""), IF(_xlpm.codeType="F","F", IF(_xlpm.codeType="M", _xlfn.IFS( _xlpm.mid="AHU", "M-E1", AND(_xlpm.kw>=0.37, _xlpm.kw<=15), "M-A1", AND(_xlpm.kw>=18.5, _xlpm.kw<22), "M-A1", AND(_xlpm.kw>=22, _xlpm.kw<=37), "M-B1", AND(_xlpm.kw>=45, _xlpm.kw<=75), "M-B1", AND(_xlpm.kw>=90, _xlpm.kw<=110), "M-B1", AND(_xlpm.kw>110, _xlpm.kw<132), "M-C1", AND(_xlpm.kw>=132, _xlpm.kw<=200), "M-D1", _xlpm.kw>200, "M-E1", TRUE, "<review>" ), "<review>" ) ) )} -> F | F14: {=_xlfn.LET( _xlpm.tag, UPPER(TRIM(A14)), _xlpm.kw, N(C14), _xlpm.flc, N(D14), _xlpm.I_MCCB, 160, _xlpm.I_ACB, 630, _xlpm.tACB, "400V Air Circuit Breaker(ACB) Feeder Cubicle (per Dwg LV1)", _xlpm.tMCCB_HI, "400V MCCB Feeder Cubicle (I > 160A, per Dwg LV3)", _xlpm.tMCCB_LO, "400V MCCB Feeder Cubicle (I < 160A, per Dwg LV4)", _xlpm.tM_LV_DOL, "400V DOL Motor Starter Cubicle", _xlpm.parts, _xlfn.TEXTSPLIT(_xlpm.tag,"-"), _xlpm.mid, IF(COUNTA(_xlpm.parts)>=2, INDEX(_xlpm.parts,1,2), ""), _xlpm.mapCodes, {"AHU";"CWP";"EF";"ACWC";"ACCU";"EDH";"WWG";"WWP";"HD"}, _xlpm.mapType, {"M";"M";"M";"F";"F";"F";"F";"F";"F"}, _xlpm.codeType, _xlfn.XLOOKUP(_xlpm.mid, _xlpm.mapCodes, _xlpm.mapType, ""), _xlpm.motorClass, IF(_xlpm.codeType="M", _xlfn.IFS( _xlpm.mid="AHU", "M-E1", AND(_xlpm.kw>=0.37, _xlpm.kw<=15), "M-A1", AND(_xlpm.kw>=18.5, _xlpm.kw<22), "M-A1", AND(_xlpm.kw>=22, _xlpm.kw<=37), "M-B1", AND(_xlpm.kw>=45, _xlpm.kw<=75), "M-B1", AND(_xlpm.kw>=90, _xlpm.kw<=110), "M-B1", AND(_xlpm.kw>110, _xlpm.kw<132), "M-C1", AND(_xlpm.kw>=132, _xlpm.kw<=200), "M-D1", _xlpm.kw>200, "M-E1", TRUE, "<review>" ), "" ), _xlpm.FeederSel, IF(_xlpm.flc>=_xlpm.I_ACB, _xlpm.tACB, IF(_xlpm.flc>_xlpm.I_MCCB, _xlpm.tMCCB_HI, _xlpm.tMCCB_LO)), IF(_xlpm.codeType="F", _xlpm.FeederSel, IF(_xlpm.codeType="M", IF(_xlpm.motorClass="<review>", "<review>", _xlpm.tM_LV_DOL), "CHECK TAG CODE: "&_xlpm.mid ) ) )} -> 400V MCCB Feeder Cubicle (I < 160A, per Dwg LV4) | G14: {=_xlfn.LET( _xlpm.c, UPPER(TRIM(_81IK6100018[[#This Row],[Starter Type]])), _xlpm.kw, N(_81IK6100018[[#This Row],[RATED POWER]]), _xlpm.flc, N(_81IK6100018[[#This Row],[FULL LOAD CURRENT]]), _xlpm.feederType, IFERROR( _xlfn.IFS( _xlpm.c="M-A1", "M_A1", _xlpm.c="M-B1", "M_B1", _xlpm.c="M-C1", "M_C1", _xlpm.c="M-D1", "M_D1", _xlpm.c="M-E1", "M_E1", _xlpm.c="U", "UPS", _xlpm.c="F", "FEEDER", _xlpm.c="L", "LIGHT", _xlpm.c="H", "HEATER", ISNUMBER(SEARCH("ACB", _xlpm.c)), "ACB", ISNUMBER(SEARCH("I > 160A", _xlpm.c)), "MCCB_HI", ISNUMBER(SEARCH("I < 160A", _xlpm.c)), "MCCB_LO", ISNUMBER(SEARCH("3PH+N+PE", _xlpm.c)), "3PNPE", ISNUMBER(SEARCH("SCR", _xlpm.c)), "SCR", ISNUMBER(SEARCH("VSD", _xlpm.c)), "MCCB_VSD", ISNUMBER(SEARCH("FVNR", _xlpm.c)), "FVNR", TRUE, "OTHER" ), "OTHER" ), _xlpm.LowE, _xlfn.LAMBDA(_xlpm.a, IF(_xlpm.a<=50, "8E", IF(_xlpm.a<=100, "12E", "16E"))), _xlpm.HighE, _xlfn.LAMBDA(_xlpm.a, IF(_xlpm.a<=250, "16E", IF(_xlpm.a<=400, "24E", "36E"))), _xlpm.FeederE, IF(_xlpm.flc<=32, "8E/4", IF(_xlpm.flc<=160, _xlpm.LowE(_xlpm.flc), _xlpm.HighE(_xlpm.flc))), _xlfn.IFS( _xlpm.feederType="ACB", "72E", _xlpm.feederType="MCCB_LO", _xlpm.LowE(_xlpm.flc), _xlpm.feederType="MCCB_HI", _xlpm.HighE(_xlpm.flc), _xlpm.feederType="3PNPE", _xlpm.LowE(_xlpm.flc), _xlpm.feederType="SCR", IF(_xlpm.flc<=63, "8E", IF(_xlpm.flc<=125, "12E", IF(_xlpm.flc<=250, "24E", "36E"))), _xlpm.feederType="MCCB_VSD",_xlpm.HighE(_xlpm.flc), _xlpm.feederType="FVNR", IF(_xlpm.kw<=55, "16E", IF(_xlpm.kw<=90, "24E", "36E")), _xlpm.feederType="M_A1", IF(_xlpm.kw<=15, "8E/4", "8E"), _xlpm.feederType="M_B1", IF(_xlpm.kw<=37, "8E", "12E"), _xlpm.feederType="M_C1", IF(_xlpm.kw<132, "12E", "16E"), _xlpm.feederType="M_D1", "16E", _xlpm.feederType="M_E1", "24E", _xlpm.feederType="UPS", IF(_xlpm.flc<=50, "8E", IF(_xlpm.flc<=100, "12E", IF(_xlpm.flc<=250, "16E", IF(_xlpm.flc<=400, "24E", "36E")))), _xlpm.feederType="FEEDER", _xlpm.FeederE, _xlpm.feederType="LIGHT", _xlpm.FeederE, _xlpm.feederType="HEATER", _xlpm.FeederE, TRUE, "<review>" ) )} -> 8E/4 | N14: M-A1 | O14: 400V DOL Motor Starter Cubicle | P14: 16E | Q14: =COUNTIFS($E$4:$E$18,N14,$F$4:$F$18,O14,$G$4:$G$18,P14) -> 0 | R14: =ROUNDUP(Q14*0.2,0) -> 0
A15: WH-WWG-001 | C15: 2 | D15: 3.1683856 | E15: {=_xlfn.LET( _xlpm.tag, UPPER(TRIM(A15)), _xlpm.kw, N(C15), _xlpm.parts, _xlfn.TEXTSPLIT(_xlpm.tag,"-"), _xlpm.mid, IF(COUNTA(_xlpm.parts)>=2, INDEX(_xlpm.parts,1,2), ""), _xlpm.mapCodes, {"AHU";"CWP";"EF";"ACWC";"ACCU";"EDH";"WWG";"WWP";"HD"}, _xlpm.mapType, {"M";"M";"M";"F";"F";"F";"F";"F";"F"}, _xlpm.codeType, _xlfn.XLOOKUP(_xlpm.mid, _xlpm.mapCodes, _xlpm.mapType, ""), IF(_xlpm.codeType="F","F", IF(_xlpm.codeType="M", _xlfn.IFS( _xlpm.mid="AHU", "M-E1", AND(_xlpm.kw>=0.37, _xlpm.kw<=15), "M-A1", AND(_xlpm.kw>=18.5, _xlpm.kw<22), "M-A1", AND(_xlpm.kw>=22, _xlpm.kw<=37), "M-B1", AND(_xlpm.kw>=45, _xlpm.kw<=75), "M-B1", AND(_xlpm.kw>=90, _xlpm.kw<=110), "M-B1", AND(_xlpm.kw>110, _xlpm.kw<132), "M-C1", AND(_xlpm.kw>=132, _xlpm.kw<=200), "M-D1", _xlpm.kw>200, "M-E1", TRUE, "<review>" ), "<review>" ) ) )} -> F | F15: {=_xlfn.LET( _xlpm.tag, UPPER(TRIM(A15)), _xlpm.kw, N(C15), _xlpm.flc, N(D15), _xlpm.I_MCCB, 160, _xlpm.I_ACB, 630, _xlpm.tACB, "400V Air Circuit Breaker(ACB) Feeder Cubicle (per Dwg LV1)", _xlpm.tMCCB_HI, "400V MCCB Feeder Cubicle (I > 160A, per Dwg LV3)", _xlpm.tMCCB_LO, "400V MCCB Feeder Cubicle (I < 160A, per Dwg LV4)", _xlpm.tM_LV_DOL, "400V DOL Motor Starter Cubicle", _xlpm.parts, _xlfn.TEXTSPLIT(_xlpm.tag,"-"), _xlpm.mid, IF(COUNTA(_xlpm.parts)>=2, INDEX(_xlpm.parts,1,2), ""), _xlpm.mapCodes, {"AHU";"CWP";"EF";"ACWC";"ACCU";"EDH";"WWG";"WWP";"HD"}, _xlpm.mapType, {"M";"M";"M";"F";"F";"F";"F";"F";"F"}, _xlpm.codeType, _xlfn.XLOOKUP(_xlpm.mid, _xlpm.mapCodes, _xlpm.mapType, ""), _xlpm.motorClass, IF(_xlpm.codeType="M", _xlfn.IFS( _xlpm.mid="AHU", "M-E1", AND(_xlpm.kw>=0.37, _xlpm.kw<=15), "M-A1", AND(_xlpm.kw>=18.5, _xlpm.kw<22), "M-A1", AND(_xlpm.kw>=22, _xlpm.kw<=37), "M-B1", AND(_xlpm.kw>=45, _xlpm.kw<=75), "M-B1", AND(_xlpm.kw>=90, _xlpm.kw<=110), "M-B1", AND(_xlpm.kw>110, _xlpm.kw<132), "M-C1", AND(_xlpm.kw>=132, _xlpm.kw<=200), "M-D1", _xlpm.kw>200, "M-E1", TRUE, "<review>" ), "" ), _xlpm.FeederSel, IF(_xlpm.flc>=_xlpm.I_ACB, _xlpm.tACB, IF(_xlpm.flc>_xlpm.I_MCCB, _xlpm.tMCCB_HI, _xlpm.tMCCB_LO)), IF(_xlpm.codeType="F", _xlpm.FeederSel, IF(_xlpm.codeType="M", IF(_xlpm.motorClass="<review>", "<review>", _xlpm.tM_LV_DOL), "CHECK TAG CODE: "&_xlpm.mid ) ) )} -> 400V MCCB Feeder Cubicle (I < 160A, per Dwg LV4) | G15: {=_xlfn.LET( _xlpm.c, UPPER(TRIM(_81IK6100018[[#This Row],[Starter Type]])), _xlpm.kw, N(_81IK6100018[[#This Row],[RATED POWER]]), _xlpm.flc, N(_81IK6100018[[#This Row],[FULL LOAD CURRENT]]), _xlpm.feederType, IFERROR( _xlfn.IFS( _xlpm.c="M-A1", "M_A1", _xlpm.c="M-B1", "M_B1", _xlpm.c="M-C1", "M_C1", _xlpm.c="M-D1", "M_D1", _xlpm.c="M-E1", "M_E1", _xlpm.c="U", "UPS", _xlpm.c="F", "FEEDER", _xlpm.c="L", "LIGHT", _xlpm.c="H", "HEATER", ISNUMBER(SEARCH("ACB", _xlpm.c)), "ACB", ISNUMBER(SEARCH("I > 160A", _xlpm.c)), "MCCB_HI", ISNUMBER(SEARCH("I < 160A", _xlpm.c)), "MCCB_LO", ISNUMBER(SEARCH("3PH+N+PE", _xlpm.c)), "3PNPE", ISNUMBER(SEARCH("SCR", _xlpm.c)), "SCR", ISNUMBER(SEARCH("VSD", _xlpm.c)), "MCCB_VSD", ISNUMBER(SEARCH("FVNR", _xlpm.c)), "FVNR", TRUE, "OTHER" ), "OTHER" ), _xlpm.LowE, _xlfn.LAMBDA(_xlpm.a, IF(_xlpm.a<=50, "8E", IF(_xlpm.a<=100, "12E", "16E"))), _xlpm.HighE, _xlfn.LAMBDA(_xlpm.a, IF(_xlpm.a<=250, "16E", IF(_xlpm.a<=400, "24E", "36E"))), _xlpm.FeederE, IF(_xlpm.flc<=32, "8E/2", IF(_xlpm.flc<=160, _xlpm.LowE(_xlpm.flc), _xlpm.HighE(_xlpm.flc))), _xlfn.IFS( _xlpm.feederType="ACB", "72E", _xlpm.feederType="MCCB_LO", _xlpm.LowE(_xlpm.flc), _xlpm.feederType="MCCB_HI", _xlpm.HighE(_xlpm.flc), _xlpm.feederType="3PNPE", _xlpm.LowE(_xlpm.flc), _xlpm.feederType="SCR", IF(_xlpm.flc<=63, "8E", IF(_xlpm.flc<=125, "12E", IF(_xlpm.flc<=250, "24E", "36E"))), _xlpm.feederType="MCCB_VSD",_xlpm.HighE(_xlpm.flc), _xlpm.feederType="FVNR", IF(_xlpm.kw<=55, "16E", IF(_xlpm.kw<=90, "24E", "36E")), _xlpm.feederType="M_A1", IF(_xlpm.kw<=15, "8E/2", "8E"), _xlpm.feederType="M_B1", IF(_xlpm.kw<=37, "8E", "12E"), _xlpm.feederType="M_C1", IF(_xlpm.kw<132, "12E", "16E"), _xlpm.feederType="M_D1", "16E", _xlpm.feederType="M_E1", "24E", _xlpm.feederType="UPS", IF(_xlpm.flc<=50, "8E", IF(_xlpm.flc<=100, "12E", IF(_xlpm.flc<=250, "16E", IF(_xlpm.flc<=400, "24E", "36E")))), _xlpm.feederType="FEEDER", _xlpm.FeederE, _xlpm.feederType="LIGHT", _xlpm.FeederE, _xlpm.feederType="HEATER", _xlpm.FeederE, TRUE, "<review>" ) )} -> 8E/2 | N15: L | O15: 400V 3Ph+N+PE Feeder Cubicle (per Dwg LV5) | P15: 8E | Q15: =COUNTIFS($E$4:$E$18,N15,$F$4:$F$18,O15,$G$4:$G$18,P15) -> 0 | R15: =ROUNDUP(Q15*0.2,0) -> 0
